Workbook

Sheet ALT-4(jsl)
D1: sqm | E1: py
B2: 법정최대건축면적 | D2: =+E15*F24 | E2: =+D2*0.3025
B3: 법정최대연면적 | D3: =+E15*F25 | E3: =+D3*0.3025 | F3: =+D3*0.015 | G3: =+F3/12 | I3: =+D3/D2 | N3: =+E15/2 | P3: =+N3*0.6 | S3: =+R3*0.3025
D4: =+P29 | E4: =+D3-D4 | W4: =+T4+U4 | X4: =+W4-V4
B6: ■ 설계개요 | C6: ALT-1 [상가주택] | I6: ■ 층별면적표 (층고 3M) | AD6: 단위 : ㎡
B7: 공사명 | J7: 근린생활시설 | L7: 다가구 | N7: 공용 | P7: 계 | R7: 근린생활시설 | U7: - | X7: 기계/전기실 | Y7: 주차장 | Z7: 부대시설 (관리사무실) | AA7: 합계 | AB7: 비고
B8: 대지현황 | C8: 대지위치 | J8: SQM | K8: PY | L8: SQM | M8: PY | N8: SQM | O8: PY | P8: SQM | Q8: PY | R8: 전용 | S8: 공용 | T8: 계 | U8: 전용 | V8: 공용 | W8: 계
C9: 대지면적 | D9: =+토지내역!B3 | E9: =+토지내역!C3 | F9: =E9*0.3025
D10: =+토지내역!B4 | E10: =+토지내역!C4 | F10: =E10*0.3025
D11: =+토지내역!B5 | E11: =+토지내역!C5 | F11: =E11*0.3025
D12: =+토지내역!B6 | E12: =+토지내역!C6 | F12: =E12*0.3025
D13: 공제면적 | E13: =+토지내역!C28 | F13: =E13*0.3025 | AF13: 주차대수
D14: 공제면적 | E14: =+토지내역!C26 | F14: =E14*0.3025 | AG14: =L25+L26 | AH14: =+AG14/65 | AI14: =+AF14+AH14
D15: 합계 | E15: =+E9+E10-E13-E14 | F15: =E15*0.3025
C16: 지역/지구 | D16: =+Sheet1!E4
C17: 도로현황
B18: 건설규모 | C18: 용도
C19: 규모
C20: 건축면적 | E20: =D20*0.3025
C21: 연면적 | D21: 지상 | E21: =AA29 | F21: =E21*0.3025
D22: 지하 | E22: =AA36 | F22: =E22*0.3025 | P22: =J22+N22
D23: 합계 | E23: =SUM(E21:E22) | F23: =E23*0.3025 | P23: =J23+N23 | AF23: 전체 | AG23: 전용 | AR23: 벽체공용
C24: 건폐율 | D24: =D20/$E$15 | E24: 법정: | P24: =J24+N24 | AE24: A | AP24: =SUM(AG24:AO24) | AR24: =+AF24-AP24 | AT24: =+AR24*AS24
C25: 용적율 | D25: =(P29)/$E$15 | E25: 법정: | I25: 4층 | K25: =+J25*0.3025 | M25: =+L25*0.3025 | O25: =+N25*0.3025 | P25: =J25+N25+L25 | Q25: =+P25*0.3025 | T25: =R25+S25 | W25: =+U25+V25 | AA25: =+SUM(P25,T25,W25,X25,Y25,Z25) | AB25: 1가구
B26: 주차시설 | C26: 법정 | D26: 주택 | G26: =AI14 | K26: =+J26*0.3025 | M26: =+L26*0.3025 | O26: =+N26*0.3025 | P26: =J26+N26+L26 | Q26: =+P26*0.3025 | T26: =R26+S26 | W26: =+U26+V26 | AA26: =+SUM(P26,T26,W26,X26,Y26,Z26)
D27: 근생 | E27: =L63 | G27: =E27/134 | K27: =+J27*0.3025 | M27: =+L27*0.3025 | O27: =+N27*0.3025 | P27: =J27+N27+L27 | Q27: =+P27*0.3025 | T27: =R27+S27 | W27: =+U27+V27 | AA27: =+SUM(P27,T27,W27,X27,Y27,Z27) | AB27: 1가구
K28: =+J28*0.3025 | M28: =+L28*0.3025 | O28: =+N28*0.3025 | P28: =J28+N28+L28 | Q28: =+P28*0.3025 | T28: =R28+S28 | W28: =+U28+V28 | AA28: =+SUM(P28,T28,W28,X28,Y28,Z28) | AB28: 제1종근린생활시설(휴게음식점)
I29: 지상층계 | J29: =SUM(J25:J28) | K29: =+J29*0.3025 | L29: =SUM(L25:L28) | M29: =+L29*0.3025 | N29: =SUM(N9:N28) | O29: =+N29*0.3025 | P29: =SUM(P25:P28) | Q29: =+P29*0.3025 | T29: =SUM(T9:T28) | U29: =SUM(U9:U28) | V29: =SUM(V9:V28) | W29: =SUM(W9:W28) | X29: =SUM(X9:X28) | Y29: =SUM(Y9:Y28) | Z29: =SUM(Z9:Z28) | AA29: =+SUM(P29,T29,W29,X29,Y29,Z29) | AF29: =+J28+N28+J30+N30 | AG29: =+AF29/134
D30: 계 | K30: =+J30*0.3025 | M30: =+L30*0.3025 | O30: =+N30*0.3025 | P30: =J30+N30+L30 | Q30: =+P30*0.3025 | T30: =R30+S30 | U30: =+AE30 | V30: =+AF30+AJ30 | W30: =+U30+V30 | AA30: =+SUM(P30,T30,W30,X30,Y30,Z30) | AB30: 제2종근린생활시설(사무소),주택(창고)
C31: 계획 | D31: 지상 | E31: 자주식 주차 | T31: =R31+S31 | W31: =+U31+V31 | AA31: =+SUM(P31,T31,W31,X31,Y31,Z31)
D32: 지하 | E32: 자주식 주차 | P32: =J32+N32 | T32: =R32+S32 | W32: =+U32+V32 | Y32: =+AA32-X32 | AA32: =+AH32
AH33: =+AE33-AF33
B34: 조경면적 | C34: 법정 | D34: =E15 | F34: =D34*E34 | P34: =J34+N34 | T34: =R34+S34 | W34: =+U34+V34 | AA34: =+SUM(P34,T34,W34,X34,Y34,Z34)
P35: =J35+N35 | T35: =R35+S35 | W35: =+U35+V35 | AA35: =+SUM(P35,T35,W35,X35,Y35,Z35) | AK35: =+AI35/AJ35
C36: 계획 | D36: =+D34 | E36: =+E34 | F36: =D36*E36 | I36: 지하층계 | J36: =SUM(J30:J35) | K36: =+J36*0.3025 | L36: =SUM(L30:L35) | M36: =SUM(M30:M35) | N36: =SUM(N30:N35) | O36: =+N36*0.3025 | P36: =SUM(P30:P35) | Q36: =+P36*0.3025 | R36: =SUM(R30:R35) | S36: =SUM(S30:S35) | T36: =SUM(T30:T35) | U36: =SUM(U30:U35) | V36: =SUM(V30:V35) | W36: =SUM(W30:W35) | X36: =SUM(X30:X35) | Y36: =SUM(Y30:Y35) | Z36: =SUM(Z30:Z35) | AA36: =+SUM(P36,T36,W36,X36,Y36,Z36) | AK36: =+AI36/AJ36
B37: 커뮤니티 | C37: 법정 | I37: 합계 | J37: =J29+J36 | K37: =+J37*0.3025 | L37: =L29+L36 | M37: =+L37*0.3025 | N37: =N29+N36 | O37: =+N37*0.3025 | P37: =P29+P36 | Q37: =+P37*0.3025 | R37: =R29+R36 | S37: =S29+S36 | T37: =T29+T36 | U37: =U29+U36 | V37: =V29+V36 | W37: =W29+W36 | X37: =X29+X36 | Y37: =Y29+Y36 | Z37: =Z29+Z36 | AA37: =+SUM(P37,T37,W37,X37,Y37,Z37) | AI37: =+AH36+AK36+AK35
C38: 계획 | J38: =J37*0.3025 | L38: =L37*0.3025 | N38: =N37*0.3025 | P38: =P37*0.3025 | R38: =R37*0.3025 | S38: =S37*0.3025 | T38: =T37*0.3025 | U38: =U37*0.3025 | V38: =V37*0.3025 | W38: =W37*0.3025 | X38: =X37*0.3025 | Y38: =Y37*0.3025 | ... AA38: =AA37*0.3025
B40: ■ 용도별면적표 | AA40: 단위 : ㎡ (평)
B41: 구 분 | C41: 전용면적 | E41: 공용면적(복도,코아) | G41: 기타공용면적 (부대시설) | I41: 기계/전기실 | N41: 소 계 (시설면적) | U41: 주차장면적 | X41: 합 계 (계약면적) | Z41: 비 율 | AA41: 대지지분
B42: 오피스텔
...

Sheet ALT-3(osl)
D1: sqm | E1: py
B2: 법정최대건축면적 | D2: =+E15*F24 | E2: =+D2*0.3025
B3: 법정최대연면적 | D3: =+E15*F25 | E3: =+D3*0.3025 | F3: =+D3*0.015 | G3: =+F3/12 | I3: =+D3/D2 | N3: =+E15/2 | P3: =+N3*0.6 | S3: =+R3*0.3025
D4: =+P29 | E4: =+D3-D4 | W4: =+T4+U4 | X4: =+W4-V4
AD5: 2022-10-25-OSL1
B6: ■ 설계개요 | C6: ALT-1 [상가주택] | I6: ■ 층별면적표 (층고 3M) | AD6: 단위 : ㎡
B7: 공사명 | C7: 위례신도시 D1-2-4-1구역 | J7: 근린생활시설 | L7: 다가구 | N7: 공용 | P7: 계 | R7: 근린생활시설 | U7: - | X7: 기계/전기실 | Y7: 주차장 | Z7: 부대시설 (관리사무실) | AA7: 합계 | AB7: 비고
B8: 대지현황 | C8: 대지위치 | D8: 위례신도시 D1-2-4-1구역 | J8: SQM | K8: PY | L8: SQM | M8: PY | N8: SQM | O8: PY | P8: SQM | Q8: PY | R8: 전용 | S8: 공용 | T8: 계 | U8: 전용 | V8: 공용 | W8: 계
C9: 대지면적 | D9: =+토지내역!B3 | E9: =+토지내역!C3 | F9: =E9*0.3025
D10: =+토지내역!B4 | E10: =+토지내역!C4 | F10: =E10*0.3025
D11: =+토지내역!B5 | E11: =+토지내역!C5 | F11: =E11*0.3025
D12: =+토지내역!B6 | E12: =+토지내역!C6 | F12: =E12*0.3025
D13: 공제면적 | E13: =+토지내역!C28 | F13: =E13*0.3025 | AF13: 주차대수
D14: 공제면적 | E14: =+토지내역!C26 | F14: =E14*0.3025 | AG14: =L25+L26 | AH14: =+AG14/65 | AI14: =+AF14+AH14
D15: 합계 | E15: =+E9+E10-E13-E14 | F15: =E15*0.3025
C16: 지역/지구 | D16: =+Sheet1!E4
C17: 도로현황
B18: 건설규모 | C18: 용도 | D18: 근린생활시설, 다가구주택
C19: 규모 | D19: 지하1층, 지상4층
C20: 건축면적 | E20: =D20*0.3025
C21: 연면적 | D21: 지상 | E21: =AA29 | F21: =E21*0.3025
D22: 지하 | E22: =AA36 | F22: =E22*0.3025 | P22: =J22+N22
D23: 합계 | E23: =SUM(E21:E22) | F23: =E23*0.3025 | P23: =J23+N23 | AF23: 전체 | AG23: 전용 | AR23: 벽체공용
C24: 건폐율 | D24: =D20/$E$15 | E24: 법정: | P24: =J24+N24 | AE24: A | AP24: =SUM(AG24:AO24) | AR24: =+AF24-AP24 | AT24: =+AR24*AS24
C25: 용적율 | D25: =(P29)/$E$15 | E25: 법정: | I25: 4층 | K25: =+J25*0.3025 | M25: =+L25*0.3025 | O25: =+N25*0.3025 | P25: =J25+N25+L25 | Q25: =+P25*0.3025 | T25: =R25+S25 | W25: =+U25+V25 | AA25: =+SUM(P25,T25,W25,X25,Y25,Z25) | AB25: 1가구
B26: 주차시설 | C26: 법정 | D26: 주택 | G26: =AI14 | K26: =+J26*0.3025 | M26: =+L26*0.3025 | O26: =+N26*0.3025 | P26: =J26+N26+L26 | Q26: =+P26*0.3025 | T26: =R26+S26 | W26: =+U26+V26 | AA26: =+SUM(P26,T26,W26,X26,Y26,Z26)
D27: 근생 | E27: =G63 | K27: =+J27*0.3025 | M27: =+L27*0.3025 | O27: =+N27*0.3025 | P27: =J27+N27+L27 | Q27: =+P27*0.3025 | T27: =R27+S27 | W27: =+U27+V27 | AA27: =+SUM(P27,T27,W27,X27,Y27,Z27) | AB27: 1가구
K28: =+J28*0.3025 | M28: =+L28*0.3025 | O28: =+N28*0.3025 | P28: =J28+N28+L28 | Q28: =+P28*0.3025 | T28: =R28+S28 | W28: =+U28+V28 | AA28: =+SUM(P28,T28,W28,X28,Y28,Z28) | AB28: 근린생활시설
I29: 지상층계 | J29: =SUM(J25:J28) | K29: =+J29*0.3025 | L29: =SUM(L25:L28) | M29: =+L29*0.3025 | N29: =SUM(N9:N28) | O29: =+N29*0.3025 | P29: =SUM(P25:P28) | Q29: =+P29*0.3025 | T29: =SUM(T9:T28) | U29: =SUM(U9:U28) | V29: =SUM(V9:V28) | W29: =SUM(W9:W28) | X29: =SUM(X9:X28) | Y29: =SUM(Y9:Y28) | Z29: =SUM(Z9:Z28) | AA29: =+SUM(P29,T29,W29,X29,Y29,Z29) | AB29: 근린생활시설 | AF29: =+J28+N28+J30+N30 | AG29: =+AF29/134
D30: 계 | K30: =+J30*0.3025 | O30: =+N30*0.3025 | P30: =J30+N30 | Q30: =+P30*0.3025 | T30: =R30+S30 | U30: =+AE30 | V30: =+AF30+AJ30 | W30: =+U30+V30 | AA30: =+SUM(P30,T30,W30,X30,Y30,Z30) | AB30: 근린생활시설
C31: 계획 | D31: 지상 | E31: 자주식 주차 | T31: =R31+S31 | W31: =+U31+V31 | AA31: =+SUM(P31,T31,W31,X31,Y31,Z31)
D32: 지하 | E32: 자주식 주차 | P32: =J32+N32 | T32: =R32+S32 | W32: =+U32+V32 | Y32: =+AA32-X32 | AA32: =+AH32
AH33: =+AE33-AF33
B34: 조경면적 | C34: 법정 | D34: =E15 | F34: =D34*E34 | P34: =J34+N34 | T34: =R34+S34 | W34: =+U34+V34 | AA34: =+SUM(P34,T34,W34,X34,Y34,Z34)
P35: =J35+N35 | T35: =R35+S35 | W35: =+U35+V35 | AA35: =+SUM(P35,T35,W35,X35,Y35,Z35) | AK35: =+AI35/AJ35
C36: 계획 | D36: =+D34 | E36: =+E34 | F36: =D36*E36 | I36: 지하층계 | J36: =SUM(J30:J35) | K36: =+J36*0.3025 | N36: =SUM(N30:N35) | O36: =+N36*0.3025 | P36: =SUM(P30:P35) | Q36: =+P36*0.3025 | R36: =SUM(R30:R35) | S36: =SUM(S30:S35) | T36: =SUM(T30:T35) | U36: =SUM(U30:U35) | V36: =SUM(V30:V35) | W36: =SUM(W30:W35) | X36: =SUM(X30:X35) | Y36: =SUM(Y30:Y35) | Z36: =SUM(Z30:Z35) | AA36: =+SUM(P36,T36,W36,X36,Y36,Z36) | AK36: =+AI36/AJ36
B37: 커뮤니티 | C37: 법정 | I37: 합계 | J37: =J29+J36 | K37: =+J37*0.3025 | L37: =L29+L36 | M37: =+L37*0.3025 | N37: =N29+N36 | O37: =+N37*0.3025 | P37: =P29+P36 | Q37: =+P37*0.3025 | R37: =R29+R36 | S37: =S29+S36 | T37: =T29+T36 | U37: =U29+U36 | V37: =V29+V36 | W37: =W29+W36 | X37: =X29+X36 | Y37: =Y29+Y36 | Z37: =Z29+Z36 | AA37: =+SUM(P37,T37,W37,X37,Y37,Z37) | AI37: =+AH36+AK36+AK35
C38: 계획 | J38: =J37*0.3025 | L38: =L37*0.3025 | N38: =N37*0.3025 | P38: =P37*0.3025 | R38: =R37*0.3025 | S38: =S37*0.3025 | T38: =T37*0.3025 | U38: =U37*0.3025 | V38: =V37*0.3025 | W38: =W37*0.3025 | X38: =X37*0.3025 | Y38: =Y37*0.3025 | ... AA38: =AA37*0.3025
B40: ■ 용도별면적표 | AA40: 단위 : ㎡ (평)
B41: 구 분 | C41: 전용면적 | E41: 공용면적(복도,코아) | G41: 기타공용면적 (부대시설) | I41: 기계/전기실 | N41: 소 계 (시설면적) | U41: 주차장면적 | X41: 합 계 (계약면적) | Z41: 비 율 | AA41: 대지지분
...

Sheet ALT-2
D1: sqm | E1: py
B2: 법정최대건축면적 | D2: =+E15*F24 | E2: =+D2*0.3025
B3: 법정최대연면적 | D3: =+E15*F25 | E3: =+D3*0.3025 | F3: =+D3*0.015 | G3: =+F3/12 | I3: =+D3/D2 | N3: =+E15/2 | P3: =+N3*0.6 | S3: =+R3*0.3025
D4: =+P29 | E4: =+D3-D4 | W4: =+T4+U4 | X4: =+W4-V4
AD5: 2022-10-25-OSL1
B6: ■ 설계개요 | C6: ALT-1 [상가주택] | I6: ■ 층별면적표 (층고 3M) | M6: =+L6/65 | AD6: 단위 : ㎡
B7: 공사명 | C7: 위례신도시 D1-2-4-1구역 | J7: 근린생활시설 | L7: 다가구 | N7: 공용 | P7: 계 | R7: 근린생활시설 | U7: - | X7: 기계/전기실 | Y7: 주차장 | Z7: 부대시설 (관리사무실) | AA7: 합계 | AB7: 비고
B8: 대지현황 | C8: 대지위치 | D8: 위례신도시 D1-2-2-3구역 | J8: SQM | K8: PY | L8: SQM | M8: PY | N8: SQM | O8: PY | P8: SQM | Q8: PY | R8: 전용 | S8: 공용 | T8: 계 | U8: 전용 | V8: 공용 | W8: 계
C9: 대지면적 | D9: =+토지내역!B3 | E9: =+토지내역!C3 | F9: =E9*0.3025
D10: =+토지내역!B4 | E10: =+토지내역!C4 | F10: =E10*0.3025
D11: =+토지내역!B5 | E11: =+토지내역!C5 | F11: =E11*0.3025
D12: =+토지내역!B6 | E12: =+토지내역!C6 | F12: =E12*0.3025
D13: 공제면적 | E13: =+토지내역!C28 | F13: =E13*0.3025
D14: 공제면적 | E14: =+토지내역!C26 | F14: =E14*0.3025
D15: 합계 | E15: =+E9+E10-E13-E14 | F15: =E15*0.3025
C16: 지역/지구 | D16: =+Sheet1!E4
C17: 도로현황
B18: 건설규모 | C18: 용도 | D18: 근린생활시설, 다가구주택
C19: 규모 | D19: 지하1층, 지상4층
C20: 건축면적 | E20: =D20*0.3025
C21: 연면적 | D21: 지상 | E21: =AA29 | F21: =E21*0.3025
D22: 지하 | E22: =AA36 | F22: =E22*0.3025 | P22: =J22+N22
D23: 합계 | E23: =SUM(E21:E22) | F23: =E23*0.3025 | P23: =J23+N23 | AF23: 전체 | AG23: 전용 | AR23: 벽체공용
C24: 건폐율 | D24: =D20/$E$15 | E24: 법정: | P24: =J24+N24 | AE24: A | AP24: =SUM(AG24:AO24) | AR24: =+AF24-AP24 | AT24: =+AR24*AS24
C25: 용적율 | D25: =(P29)/$E$15 | E25: 법정: | I25: 4층 | K25: =+J25*0.3025 | M25: =+L25*0.3025 | O25: =+N25*0.3025 | P25: =J25+N25+L25 | Q25: =+P25*0.3025 | T25: =R25+S25 | W25: =+U25+V25 | AA25: =+SUM(P25,T25,W25,X25,Y25,Z25)
B26: 주차시설 | C26: 법정 | D26: 주택 | K26: =+J26*0.3025 | M26: =+L26*0.3025 | O26: =+N26*0.3025 | P26: =J26+N26+L26 | Q26: =+P26*0.3025 | T26: =R26+S26 | W26: =+U26+V26 | AA26: =+SUM(P26,T26,W26,X26,Y26,Z26)
D27: 근생 | E27: =+J37+N28+N30 | G27: =+E27/134 | K27: =+J27*0.3025 | M27: =+L27*0.3025 | O27: =+N27*0.3025 | P27: =J27+N27+L27 | Q27: =+P27*0.3025 | T27: =R27+S27 | W27: =+U27+V27 | AA27: =+SUM(P27,T27,W27,X27,Y27,Z27)
K28: =+J28*0.3025 | M28: =+L28*0.3025 | O28: =+N28*0.3025 | P28: =J28+N28+L28 | Q28: =+P28*0.3025 | T28: =R28+S28 | W28: =+U28+V28 | AA28: =+SUM(P28,T28,W28,X28,Y28,Z28)
I29: 지상층계 | J29: =SUM(J25:J28) | K29: =+J29*0.3025 | L29: =SUM(L25:L28) | M29: =+L29*0.3025 | N29: =SUM(N9:N28) | O29: =+N29*0.3025 | P29: =SUM(P25:P28) | Q29: =+P29*0.3025 | T29: =SUM(T9:T28) | U29: =SUM(U9:U28) | V29: =SUM(V9:V28) | W29: =SUM(W9:W28) | X29: =SUM(X9:X28) | Y29: =SUM(Y9:Y28) | Z29: =SUM(Z9:Z28) | AA29: =+SUM(P29,T29,W29,X29,Y29,Z29) | AF29: =+J28+N28+J30+N30 | AG29: =+AF29/134
D30: 계 | K30: =+J30*0.3025 | O30: =+N30*0.3025 | P30: =J30+N30 | Q30: =+P30*0.3025 | T30: =R30+S30 | U30: =+AE30 | V30: =+AF30+AJ30 | W30: =+U30+V30 | AA30: =+SUM(P30,T30,W30,X30,Y30,Z30)
C31: 계획 | D31: 지상 | E31: 자주식 주차 | T31: =R31+S31 | W31: =+U31+V31 | AA31: =+SUM(P31,T31,W31,X31,Y31,Z31)
D32: 지하 | E32: 자주식 주차 | P32: =J32+N32 | T32: =R32+S32 | W32: =+U32+V32 | Y32: =+AA32-X32 | AA32: =+AH32
AH33: =+AE33-AF33
B34: 조경면적 | C34: 법정 | D34: =E15 | F34: =D34*E34 | P34: =J34+N34 | T34: =R34+S34 | W34: =+U34+V34 | AA34: =+SUM(P34,T34,W34,X34,Y34,Z34)
P35: =J35+N35 | T35: =R35+S35 | W35: =+U35+V35 | AA35: =+SUM(P35,T35,W35,X35,Y35,Z35) | AK35: =+AI35/AJ35
C36: 계획 | D36: =+D34 | E36: =+E34 | F36: =D36*E36 | I36: 지하층계 | J36: =SUM(J30:J35) | K36: =+J36*0.3025 | N36: =SUM(N30:N35) | O36: =+N36*0.3025 | P36: =SUM(P30:P35) | Q36: =+P36*0.3025 | R36: =SUM(R30:R35) | S36: =SUM(S30:S35) | T36: =SUM(T30:T35) | U36: =SUM(U30:U35) | V36: =SUM(V30:V35) | W36: =SUM(W30:W35) | X36: =SUM(X30:X35) | Y36: =SUM(Y30:Y35) | Z36: =SUM(Z30:Z35) | AA36: =+SUM(P36,T36,W36,X36,Y36,Z36) | AK36: =+AI36/AJ36
B37: 커뮤니티 | C37: 법정 | I37: 합계 | J37: =J29+J36 | K37: =+J37*0.3025 | L37: =L29+L36 | M37: =+L37*0.3025 | N37: =N29+N36 | O37: =+N37*0.3025 | P37: =P29+P36 | Q37: =+P37*0.3025 | R37: =R29+R36 | S37: =S29+S36 | T37: =T29+T36 | U37: =U29+U36 | V37: =V29+V36 | W37: =W29+W36 | X37: =X29+X36 | Y37: =Y29+Y36 | Z37: =Z29+Z36 | AA37: =+SUM(P37,T37,W37,X37,Y37,Z37) | AI37: =+AH36+AK36+AK35
C38: 계획 | J38: =J37*0.3025 | L38: =L37*0.3025 | N38: =N37*0.3025 | P38: =P37*0.3025 | R38: =R37*0.3025 | S38: =S37*0.3025 | T38: =T37*0.3025 | U38: =U37*0.3025 | V38: =V37*0.3025 | W38: =W37*0.3025 | X38: =X37*0.3025 | Y38: =Y37*0.3025 | ... AA38: =AA37*0.3025
B40: ■ 용도별면적표 | AA40: 단위 : ㎡ (평)
B41: 구 분 | C41: 전용면적 | E41: 공용면적(복도,코아) | G41: 기타공용면적 (부대시설) | I41: 기계/전기실 | N41: 소 계 (시설면적) | U41: 주차장면적 | X41: 합 계 (계약면적) | Z41: 비 율 | AA41: 대지지분
...

Sheet ALT-1개요표
D1: sqm | E1: py
B2: 법정최대건축면적 | D2: =+E15*F24 | E2: =+D2*0.3025
B3: 법정최대연면적 | D3: =+E15*F25 | E3: =+D3*0.3025 | F3: =+D3*0.015 | G3: =+F3/12 | I3: =+D3/D2 | N3: =+E15/2 | P3: =+N3*0.6 | S3: =+R3*0.3025
D4: =+P29 | E4: =+D3-D4 | W4: =+T4+U4 | X4: =+W4-V4
AD5: 2022-10-25-OSL1
B6: ■ 설계개요 | C6: ALT-1 [상가주택] | I6: ■ 층별면적표 (층고 3M) | AD6: 단위 : ㎡
B7: 공사명 | C7: 위례신도시 D1-2-4-1구역 | J7: 근린생활시설 | L7: 다가구 | N7: 공용 | P7: 계 | R7: 근린생활시설 | U7: - | X7: 기계/전기실 | Y7: 주차장 | Z7: 부대시설 (관리사무실) | AA7: 합계 | AB7: 비고
B8: 대지현황 | C8: 대지위치 | D8: 위례신도시 D1-2-2-3구역 | J8: SQM | K8: PY | L8: SQM | M8: PY | N8: SQM | O8: PY | P8: SQM | Q8: PY | R8: 전용 | S8: 공용 | T8: 계 | U8: 전용 | V8: 공용 | W8: 계
C9: 대지면적 | D9: =+토지내역!B3 | E9: =+토지내역!C3 | F9: =E9*0.3025
D10: =+토지내역!B4 | E10: =+토지내역!C4 | F10: =E10*0.3025
D11: =+토지내역!B5 | E11: =+토지내역!C5 | F11: =E11*0.3025
D12: =+토지내역!B6 | E12: =+토지내역!C6 | F12: =E12*0.3025
D13: 공제면적 | E13: =+토지내역!C28 | F13: =E13*0.3025
D14: 공제면적 | E14: =+토지내역!C26 | F14: =E14*0.3025
D15: 합계 | E15: =+E9+E10-E13-E14 | F15: =E15*0.3025
C16: 지역/지구 | D16: =+Sheet1!E4
C17: 도로현황
B18: 건설규모 | C18: 용도 | D18: 근린생활시설, 다가구주택
C19: 규모 | D19: 지하1층, 지상4층
C20: 건축면적 | E20: =D20*0.3025
C21: 연면적 | D21: 지상 | E21: =AA29 | F21: =E21*0.3025
D22: 지하 | E22: =AA36 | F22: =E22*0.3025 | P22: =J22+N22
D23: 합계 | E23: =SUM(E21:E22) | F23: =E23*0.3025 | P23: =J23+N23 | AF23: 전체 | AG23: 전용 | AR23: 벽체공용
C24: 건폐율 | D24: =D20/$E$15 | E24: 법정: | P24: =J24+N24 | AE24: A | AP24: =SUM(AG24:AO24) | AR24: =+AF24-AP24 | AT24: =+AR24*AS24
C25: 용적율 | D25: =(P29)/$E$15 | E25: 법정: | I25: 4층 | K25: =+J25*0.3025 | M25: =+L25*0.3025 | O25: =+N25*0.3025 | P25: =J25+N25+L25 | Q25: =+P25*0.3025 | T25: =R25+S25 | W25: =+U25+V25 | AA25: =+SUM(P25,T25,W25,X25,Y25,Z25)
B26: 주차시설 | C26: 법정 | D26: 주택 | K26: =+J26*0.3025 | M26: =+L26*0.3025 | O26: =+N26*0.3025 | P26: =J26+N26+L26 | Q26: =+P26*0.3025 | T26: =R26+S26 | W26: =+U26+V26 | AA26: =+SUM(P26,T26,W26,X26,Y26,Z26) | AB26: 3룸/1가구
D27: 근생 | E27: =+J37+N28+N30 | G27: =+E27/134 | K27: =+J27*0.3025 | M27: =+L27*0.3025 | O27: =+N27*0.3025 | P27: =J27+N27+L27 | Q27: =+P27*0.3025 | T27: =R27+S27 | W27: =+U27+V27 | AA27: =+SUM(P27,T27,W27,X27,Y27,Z27) | AB27: 3룸/1가구
K28: =+J28*0.3025 | M28: =+L28*0.3025 | O28: =+N28*0.3025 | P28: =J28+N28+L28 | Q28: =+P28*0.3025 | T28: =R28+S28 | W28: =+U28+V28 | AA28: =+SUM(P28,T28,W28,X28,Y28,Z28) | AB28: 근린생활시설
I29: 지상층계 | J29: =SUM(J25:J28) | K29: =+J29*0.3025 | L29: =SUM(L25:L28) | M29: =+L29*0.3025 | N29: =SUM(N9:N28) | O29: =+N29*0.3025 | P29: =SUM(P25:P28) | Q29: =+P29*0.3025 | T29: =SUM(T9:T28) | U29: =SUM(U9:U28) | V29: =SUM(V9:V28) | W29: =SUM(W9:W28) | X29: =SUM(X9:X28) | Y29: =SUM(Y9:Y28) | Z29: =SUM(Z9:Z28) | AA29: =+SUM(P29,T29,W29,X29,Y29,Z29) | AF29: =+J28+N28+J30+N30 | AG29: =+AF29/134
D30: 계 | K30: =+J30*0.3025 | O30: =+N30*0.3025 | P30: =J30+N30 | Q30: =+P30*0.3025 | T30: =R30+S30 | U30: =+AE30 | V30: =+AF30+AJ30 | W30: =+U30+V30 | AA30: =+SUM(P30,T30,W30,X30,Y30,Z30)
C31: 계획 | D31: 지상 | E31: 자주식 주차 | T31: =R31+S31 | W31: =+U31+V31 | AA31: =+SUM(P31,T31,W31,X31,Y31,Z31)
D32: 지하 | E32: 자주식 주차 | P32: =J32+N32 | T32: =R32+S32 | W32: =+U32+V32 | Y32: =+AA32-X32 | AA32: =+AH32
AH33: =+AE33-AF33
B34: 조경면적 | C34: 법정 | D34: =E15 | F34: =D34*E34 | P34: =J34+N34 | T34: =R34+S34 | W34: =+U34+V34 | AA34: =+SUM(P34,T34,W34,X34,Y34,Z34)
P35: =J35+N35 | T35: =R35+S35 | W35: =+U35+V35 | AA35: =+SUM(P35,T35,W35,X35,Y35,Z35) | AK35: =+AI35/AJ35
C36: 계획 | D36: =+D34 | E36: =+E34 | F36: =D36*E36 | I36: 지하층계 | J36: =SUM(J30:J35) | K36: =+J36*0.3025 | N36: =SUM(N30:N35) | O36: =+N36*0.3025 | P36: =SUM(P30:P35) | Q36: =+P36*0.3025 | R36: =SUM(R30:R35) | S36: =SUM(S30:S35) | T36: =SUM(T30:T35) | U36: =SUM(U30:U35) | V36: =SUM(V30:V35) | W36: =SUM(W30:W35) | X36: =SUM(X30:X35) | Y36: =SUM(Y30:Y35) | Z36: =SUM(Z30:Z35) | AA36: =+SUM(P36,T36,W36,X36,Y36,Z36) | AK36: =+AI36/AJ36
B37: 커뮤니티 | C37: 법정 | I37: 합계 | J37: =J29+J36 | K37: =+J37*0.3025 | L37: =L29+L36 | M37: =+L37*0.3025 | N37: =N29+N36 | O37: =+N37*0.3025 | P37: =P29+P36 | Q37: =+P37*0.3025 | R37: =R29+R36 | S37: =S29+S36 | T37: =T29+T36 | U37: =U29+U36 | V37: =V29+V36 | W37: =W29+W36 | X37: =X29+X36 | Y37: =Y29+Y36 | Z37: =Z29+Z36 | AA37: =+SUM(P37,T37,W37,X37,Y37,Z37) | AI37: =+AH36+AK36+AK35
C38: 계획 | J38: =J37*0.3025 | L38: =L37*0.3025 | N38: =N37*0.3025 | P38: =P37*0.3025 | R38: =R37*0.3025 | S38: =S37*0.3025 | T38: =T37*0.3025 | U38: =U37*0.3025 | V38: =V37*0.3025 | W38: =W37*0.3025 | X38: =X37*0.3025 | Y38: =Y37*0.3025 | ... AA38: =AA37*0.3025
B40: ■ 용도별면적표 | AA40: 단위 : ㎡ (평)
B41: 구 분 | C41: 전용면적 | E41: 공용면적(복도,코아) | G41: 기타공용면적 (부대시설) | I41: 기계/전기실 | N41: 소 계 (시설면적) | U41: 주차장면적 | X41: 합 계 (계약면적) | Z41: 비 율 | AA41: 대지지분
...

Sheet ALT-1 (3)
D1: sqm | E1: py
B2: 법정최대건축면적 | D2: =+E15*F24 | E2: =+D2*0.3025
B3: 법정최대연면적 | D3: =+E15*F25 | E3: =+D3*0.3025 | F3: =+D3*0.015 | G3: =+F3/12 | I3: =+D3/D2 | N3: =+E15/2 | P3: =+N3*0.6 | S3: =+R3*0.3025
D4: =+P29 | E4: =+D3-D4 | W4: =+T4+U4 | X4: =+W4-V4
AD5: 2022-10-25-OSL1
B6: ■ 설계개요 | C6: ALT-1 [상가주택] | I6: ■ 층별면적표 (층고 3M) | AD6: 단위 : ㎡
B7: 공사명 | C7: 위례신도시 D1-2-4-1구역 | J7: 근린생활시설 | L7: 다가구 | N7: 공용 | P7: 계 | R7: 근린생활시설 | U7: - | X7: 기계/전기실 | Y7: 주차장 | Z7: 부대시설 (관리사무실) | AA7: 합계 | AB7: 비고
B8: 대지현황 | C8: 대지위치 | D8: 위례신도시 D1-2-2-3구역 | J8: SQM | K8: PY | L8: SQM | M8: PY | N8: SQM | O8: PY | P8: SQM | Q8: PY | R8: 전용 | S8: 공용 | T8: 계 | U8: 전용 | V8: 공용 | W8: 계
C9: 대지면적 | D9: =+토지내역!B3 | E9: =+토지내역!C3 | F9: =E9*0.3025
D10: =+토지내역!B4 | E10: =+토지내역!C4 | F10: =E10*0.3025
D11: =+토지내역!B5 | E11: =+토지내역!C5 | F11: =E11*0.3025
D12: =+토지내역!B6 | E12: =+토지내역!C6 | F12: =E12*0.3025
D13: 공제면적 | E13: =+토지내역!C28 | F13: =E13*0.3025
D14: 공제면적 | E14: =+토지내역!C26 | F14: =E14*0.3025
D15: 합계 | E15: =+E9+E10-E13-E14 | F15: =E15*0.3025
C16: 지역/지구 | D16: =+Sheet1!E4
C17: 도로현황
B18: 건설규모 | C18: 용도 | D18: 근린생활시설, 다가구주택
C19: 규모 | D19: 지하1층, 지상4층
C20: 건축면적 | E20: =D20*0.3025
C21: 연면적 | D21: 지상 | E21: =AA29 | F21: =E21*0.3025
D22: 지하 | E22: =AA36 | F22: =E22*0.3025 | P22: =J22+N22
D23: 합계 | E23: =SUM(E21:E22) | F23: =E23*0.3025 | P23: =J23+N23 | AF23: 전체 | AG23: 전용 | AR23: 벽체공용
C24: 건폐율 | D24: =D20/$E$15 | E24: 법정: | P24: =J24+N24 | AE24: A | AP24: =SUM(AG24:AO24) | AR24: =+AF24-AP24 | AT24: =+AR24*AS24
C25: 용적율 | D25: =(P29)/$E$15 | E25: 법정: | I25: 4층 | K25: =+J25*0.3025 | M25: =+L25*0.3025 | O25: =+N25*0.3025 | P25: =J25+N25+L25 | Q25: =+P25*0.3025 | T25: =R25+S25 | W25: =+U25+V25 | AA25: =+SUM(P25,T25,W25,X25,Y25,Z25)
B26: 주차시설 | C26: 법정 | D26: 주택 | K26: =+J26*0.3025 | M26: =+L26*0.3025 | O26: =+N26*0.3025 | P26: =J26+N26+L26 | Q26: =+P26*0.3025 | T26: =R26+S26 | W26: =+U26+V26 | AA26: =+SUM(P26,T26,W26,X26,Y26,Z26) | AB26: 3룸/1가구
D27: 근생 | E27: =+J37+N28+N30 | G27: =+E27/134 | K27: =+J27*0.3025 | M27: =+L27*0.3025 | O27: =+N27*0.3025 | P27: =J27+N27+L27 | Q27: =+P27*0.3025 | T27: =R27+S27 | W27: =+U27+V27 | AA27: =+SUM(P27,T27,W27,X27,Y27,Z27) | AB27: 3룸/1가구
K28: =+J28*0.3025 | M28: =+L28*0.3025 | O28: =+N28*0.3025 | P28: =J28+N28+L28 | Q28: =+P28*0.3025 | T28: =R28+S28 | W28: =+U28+V28 | AA28: =+SUM(P28,T28,W28,X28,Y28,Z28) | AB28: 근린생활시설
I29: 지상층계 | J29: =SUM(J25:J28) | K29: =+J29*0.3025 | L29: =SUM(L25:L28) | M29: =+L29*0.3025 | N29: =SUM(N9:N28) | O29: =+N29*0.3025 | P29: =SUM(P25:P28) | Q29: =+P29*0.3025 | T29: =SUM(T9:T28) | U29: =SUM(U9:U28) | V29: =SUM(V9:V28) | W29: =SUM(W9:W28) | X29: =SUM(X9:X28) | Y29: =SUM(Y9:Y28) | Z29: =SUM(Z9:Z28) | AA29: =+SUM(P29,T29,W29,X29,Y29,Z29) | AF29: =+J28+N28+J30+N30 | AG29: =+AF29/134
D30: 계 | K30: =+J30*0.3025 | O30: =+N30*0.3025 | P30: =J30+N30 | Q30: =+P30*0.3025 | T30: =R30+S30 | U30: =+AE30 | V30: =+AF30+AJ30 | W30: =+U30+V30 | AA30: =+SUM(P30,T30,W30,X30,Y30,Z30)
C31: 계획 | D31: 지상 | E31: 자주식 주차 | T31: =R31+S31 | W31: =+U31+V31 | AA31: =+SUM(P31,T31,W31,X31,Y31,Z31)
D32: 지하 | E32: 자주식 주차 | P32: =J32+N32 | T32: =R32+S32 | W32: =+U32+V32 | Y32: =+AA32-X32 | AA32: =+AH32
AH33: =+AE33-AF33
B34: 조경면적 | C34: 법정 | D34: =E15 | F34: =D34*E34 | P34: =J34+N34 | T34: =R34+S34 | W34: =+U34+V34 | AA34: =+SUM(P34,T34,W34,X34,Y34,Z34)
P35: =J35+N35 | T35: =R35+S35 | W35: =+U35+V35 | AA35: =+SUM(P35,T35,W35,X35,Y35,Z35) | AK35: =+AI35/AJ35
C36: 계획 | D36: =+D34 | E36: =+E34 | F36: =D36*E36 | I36: 지하층계 | J36: =SUM(J30:J35) | K36: =+J36*0.3025 | N36: =SUM(N30:N35) | O36: =+N36*0.3025 | P36: =SUM(P30:P35) | Q36: =+P36*0.3025 | R36: =SUM(R30:R35) | S36: =SUM(S30:S35) | T36: =SUM(T30:T35) | U36: =SUM(U30:U35) | V36: =SUM(V30:V35) | W36: =SUM(W30:W35) | X36: =SUM(X30:X35) | Y36: =SUM(Y30:Y35) | Z36: =SUM(Z30:Z35) | AA36: =+SUM(P36,T36,W36,X36,Y36,Z36) | AK36: =+AI36/AJ36
B37: 커뮤니티 | C37: 법정 | I37: 합계 | J37: =J29+J36 | K37: =+J37*0.3025 | L37: =L29+L36 | M37: =+L37*0.3025 | N37: =N29+N36 | O37: =+N37*0.3025 | P37: =P29+P36 | Q37: =+P37*0.3025 | R37: =R29+R36 | S37: =S29+S36 | T37: =T29+T36 | U37: =U29+U36 | V37: =V29+V36 | W37: =W29+W36 | X37: =X29+X36 | Y37: =Y29+Y36 | Z37: =Z29+Z36 | AA37: =+SUM(P37,T37,W37,X37,Y37,Z37) | AI37: =+AH36+AK36+AK35
C38: 계획 | J38: =J37*0.3025 | L38: =L37*0.3025 | N38: =N37*0.3025 | P38: =P37*0.3025 | R38: =R37*0.3025 | S38: =S37*0.3025 | T38: =T37*0.3025 | U38: =U37*0.3025 | V38: =V37*0.3025 | W38: =W37*0.3025 | X38: =X37*0.3025 | Y38: =Y37*0.3025 | ... AA38: =AA37*0.3025
B40: ■ 용도별면적표 | AA40: 단위 : ㎡ (평)
B41: 구 분 | C41: 전용면적 | E41: 공용면적(복도,코아) | G41: 기타공용면적 (부대시설) | I41: 기계/전기실 | N41: 소 계 (시설면적) | U41: 주차장면적 | X41: 합 계 (계약면적) | Z41: 비 율 | AA41: 대지지분
...

Sheet 토지내역
A1: ▣ 토지내역
A2: 지번 | C2: sqm | D2: py | E2: 공시지가 (sqm당) | F2: 공시지가 평당가 | G2: 실거래가 | H2: 실거래평당가 | I2: 비고
D3: =+ROUND(C3*0.3025,2)
D5: =+ROUND(C5*0.3025,2)
D6: =+ROUND(C6*0.3025,2)
D7: =+ROUND(C7*0.3025,2)
A29: 합계 | C29: =SUM(C3:C28) | D29: =SUM(D3:D28)
D33: =+C33*1.5
D34: =+C34*1.5
C35: =SUM(C31:C34)

Sheet Sheet1
A2: 지번 | B2: 면적 | D2: 공시지가 | E2: 지역,지구 | F2: 비고
B3: Sqm | C3: py
A4: =+토지내역!B3 | B4: =+토지내역!C3 | C4: =+ROUNDUP(B4*0.3025,2)
A5: =+토지내역!B4 | B5: =+토지내역!C4 | C5: =+ROUNDUP(B5*0.3025,2)
A6: =+토지내역!B5 | B6: =+토지내역!C5 | C6: =+ROUNDUP(B6*0.3025,2)
A8: 합계 | B8: =+B4-B7 | C8: =+ROUNDUP(B8*0.3025,2)

Sheet 지상2층 면적표
C4: 공용 | D4: 전용
B5: 201호 | E5: =SUM(C5:D5)
B6: 202호 | E6: =SUM(C6:D6)

Sheet 생태면적산출근거
C2: 가중치
A3: 자연지반녹지 | C3: 1
A4: 옥상녹화 | B4: 20cm이상 | C4: 0.6
A5: 옥상녹화 | B5: 20cm미만 | C5: 0.5
A6: 부분포장 | B6: 잔디블록 | C6: 0.5
A7: 벽면녹화 | C7: 0.4

Sheet 다락층산정(지붕)
A30: E | D30: 입면적 | G30: 체적 | J30: 다락가중평균높이
A31: 번호 | B31: 산출근거(m) | C31: 면적(㎡) | D31: 번호 | E31: 산출근거(m) | F31: 면적(㎡) | G31: 번호 | H31: 산출근거(m) | I31: 면적(㎡) | K31: 체적/바닥면적 | M31: 평균높이(m)
B32: CAD산출 | D32: A | E32: CAD산출 | G32: A | I32: =F32*H32 | J32: 평균높이 | K32: =C44 | L32: =I44 | M32: =I44/C44
B33: CAD산출 | D33: B | E33: CAD산출 | G33: B | I33: =F33*H33/3*2
B34: CAD산출 | D34: C | E34: CAD산출 | G34: C | I34: =F34*H34
B35: CAD산출 | D35: D | E35: CAD산출 | G35: D | I35: =F35*H35/3*2
B36: CAD산출 | D36: E | E36: CAD산출 | G36: E | I36: =F36*H36
B37: CAD산출 | D37: F | E37: CAD산출 | G37: F | I37: =F37*H37
B38: CAD산출 | D38: G | E38: CAD산출 | G38: G | I38: =F38*H38/3
B39: CAD산출 | D39: H | E39: CAD산출 | G39: H | I39: =F39*H39
A44: 합계 | C44: =SUM(C32:C42)-C41-C42 | G44: 합계 | I44: =SUM(I32:I42)
J45: 가중평균높이 | M45: =M32
N53: =L53/M53

Sheet 생태면적
B4: 대지면적 | E4: =+D4*0.3
B5: 공간유형별면적
B6: 공간유형 | C6: 구분 | D6: 가중치 | E6: 적용방식 | F6: 면적(㎡) | G6: 환산면적(㎡) | H6: 비고
B7: 자연지반녹지 | C7: ① | E7: 자연지반 녹지 | G7: =+ROUND(D7*F7,2)
B8: 옥상녹화 ≥ 20cm | C8: ③+④+⑤ | E8: 녹화옥상시스템 | G8: =+ROUND(D8*F8,2)
B9: 부분포장 | C9: ② | E9: 잔디블록포장 | G9: =+ROUND(D9*F9,2)
B10: 계 | F10: =SUM(F7:F9) | G10: =SUM(G7:G9)
B12: 법정 생태면적비율
B13: 계획 생태면적비율 | D13: =+G10/D4
M15: =M13-M14
B26: 대지면적 | E26: =+D26*0.3
B27: 공간유형별면적
B28: 공간유형 | C28: 구분 | D28: 가중치 | E28: 적용방식 | F28: 면적(㎡) | G28: 환산면적(㎡) | H28: 비고
B29: 자연지반녹지 | C29: ① | E29: 자연지반 녹지 | G29: =+ROUND(D29*F29,2)
B30: 옥상녹화 ≥ 20cm | C30: ③+④+⑤ | E30: 녹화옥상시스템 | G30: =+ROUND(D30*F30,2)
B31: 부분포장 | C31: ② | E31: 잔디블록포장 | G31: =+ROUND(D31*F31,2)
B32: 계 | F32: =SUM(F29:F31) | G32: =SUM(G29:G31)
B34: 법정 생태면적비율
B35: 계획 생태면적비율 | D35: =+G32/D26
B60: 대지면적 | E60: =+D60*0.3
B61: 공간유형별면적
B62: 공간유형 | C62: 구분 | D62: 가중치 | E62: 적용방식 | F62: 면적(㎡) | G62: 환산면적(㎡) | H62: 비고
B63: 자연지반녹지 | E63: 자연지반 녹지 | G63: =+ROUND(D63*F63,2)
B64: 부분포장 | E64: 잔디블럭포장 | G64: =+ROUND(D64*F64,2)
B65: 옥상녹화 | E65: 잔디블록포장 | G65: =+ROUND(D65*F65,2)
B66: 벽면녹화 | E66: 벽면녹화 | G66: =+ROUND(D66*F66,2)
B69: 계 | F69: =SUM(F63:F67) | G69: =SUM(G63:G68)
B70: 법정 생태면적비율
B71: 계획 생태면적비율 | D71: =+G69/D60
H76: =SUM(F76:G76)
F77: =F76/H76 | G77: =G76/H76
